Workbook

Sheet RAB Rev 9
A1: RAB REVISI 9
A2: BALAI MONITOR SPEKTRUM FREKUENSI RADIO KELAS I SURABAYA
A3: TAHUN : 2026
A4: Semula | I4: Menjadi
A5: KODE ANGGARAN | B5: URAIAN | C5: VOL. | D5: SATUAN | E5: HARGA SATUAN (Rp.) | F5: JUMLAH | I5: KODE ANGGARAN | J5: URAIAN | K5: VOL. | L5: SATUAN | M5: HARGA SATUAN (Rp.) | N5: JUMLAH | O5: BLOKIR 524 | P5: BLOKIR Non524 | Q5: Selisih (524) | R5: Selisih (Non 524) | S5: WAKTU PELAKSANAAN | T5: Selisih | V5: SISA ANGGARAN
A7: 1 | B7: 2 | C7: 3 | E7: 4 | F7: 5 | I7: 1 | J7: 2 | K7: 3 | M7: 4 | N7: 5 | O7: 6
A8: 059.GL | B8: Program Pengembangan dan Penguatan Infrastruktur Digital | F8: =F9 -> 3301868000 | I8: 059.GL | J8: Program Pengembangan dan Penguatan Infrastruktur Digital | N8: =N9 -> 3301868000 | V8: 1749102083
A9: 7437 | B9: Monitoring dan Pengendalian Spektrum Frekuensi Radio, Perangkat Digital, dan Kualitas Layanan Telekomunikasi | F9: =F10 -> 3301868000 | I9: 7437 | J9: Monitoring dan Pengendalian Spektrum Frekuensi Radio, Perangkat Digital, dan Kualitas Layanan Telekomunikasi | N9: =N10 -> 3301868000 | V9: 1749102083
A10: 7437.BAH | B10: Pelayanan Publik Lainnya [Base Line] | F10: =F12 -> 3301868000 | I10: 7437.BAH | J10: Pelayanan Publik Lainnya [Base Line] | N10: =N12 -> 3301868000 | O10: =SUM(O12,#REF!,#REF!,#REF!,#REF!) -> #REF! | P10: =SUM(P19:P214) -> 8928000 | Q10: =SUM(Q19:Q214) -> 0 | T10: =N10-F10 -> 0 | V10: 1732627453
B11: Lokasi : KOTA SURABAYA | J11: Lokasi : KOTA SURABAYA
A12: 7437.BAH.078 | B12: Layanan Dukungan Pengawasan Spektrum Frekuensi Radio UPT | C12: 1 | D12: Layanan | F12: =SUM(F13,F18,F36,F41) -> 3301868000 | I12: 7437.BAH.078 | J12: Layanan Dukungan Pengawasan Spektrum Frekuensi Radio UPT | K12: 1 | L12: Layanan | N12: =SUM(N13,N18,N36,N41) -> 3301868000 | O12: =SUM(O13:O214) -> #REF! | P12: =SUM(P13:P214) -> 8928000 | Q12: =SUM(Q13:Q214) -> 0 | R12: =SUM(R13:R214) -> 0 | T12: =N12-F12 -> 0 | U12: =T17+T31+T35+T45+T60+T61+T77+T78+T92+T93+T103+T106+T110+T118+T122+T123+T138+T127+T144+T157+T161+T176+T189+T193+T197+T198+T199+T200+T201+T202+T206+T207 -> 0 | V12: 1246614203
A13: 100 | B13: SBML | F13: =SUM(F14) -> 1482000000 | I13: 100 | J13: SBML | N13: =SUM(N14) -> 1415000000 | O13: =SUM(O14,O27) -> 0 | V13: 429700000
A14: A | B14: Honorarium Optimalisasi PNBP Bidang Telekomunikasi dan Penyiaran | F14: =SUM(F15) -> 1482000000 | I14: A | J14: Honorarium Optimalisasi PNBP Bidang Telekomunikasi dan Penyiaran | N14: =SUM(N15) -> 1415000000 | O14: =SUM(O15,O18,O21,O24) -> 0 | V14: 429700000
A15: 521115 | B15: Belanja Honor Operasional Satuan Kerja | F15: =F17 -> 1482000000 | I15: 521115 | J15: Belanja Honor Operasional Satuan Kerja | N15: =N17 -> 1415000000 | O15: =O17 -> 0 | V15: 429700000
B16: (KPPN. 135-Surabaya II) | J16: (KPPN. 135-Surabaya II)
B17: - Standar Biaya Masukan Lainnya (SBML) | C17: 1 | D17: Thn | E17: 1482000000 | F17: =C17*E17 -> 1482000000 | J17: - Standar Biaya Masukan Lainnya (SBML) | K17: 1 | L17: Thn | M17: 1415000000 | N17: =K17*M17 -> 1415000000 | R17: =F17-N17 -> 67000000 | T17: =N17-F17 -> -67000000 | V17: 429700000
A18: 101 | B18: Dukungan Tupoksi | F18: =F19+F32 -> 715573000 | I18: 101 | J18: Dukungan Tupoksi | N18: =N19+N32 -> 689221000 | V18: 214281809
A19: A | B19: Perjalanan Dinas Asisstensi, Bimtek, Diklat, Konsultasi dan Koordinasi dengan Kantor Pusat | F19: =SUM(F20,F23,F26,F29) -> 389533000 | I19: A | J19: Perjalanan Dinas Asisstensi, Bimtek, Diklat, Konsultasi dan Koordinasi dengan Kantor Pusat | N19: =SUM(N20,N23,N26,N29) -> 390637000 | V19: 73512809
A20: 524111 | B20: Belanja Perjalanan Dinas Biasa | F20: =F22 -> 117366000 | I20: 524111 | J20: Belanja Perjalanan Dinas Biasa | N20: =N22 -> 117366000 | V20: 42031700
B21: (KPPN. 135-Surabaya II) | J21: (KPPN. 135-Surabaya II)
B22: - Perjalanan Dinas Rutin Koordinasi dan Konsultasi dengan Kantor Pusat dan Instansi Terkait | C22: 1 | D22: Thn | E22: 117366000 | F22: =C22*E22 -> 117366000 | G22: * | J22: - Perjalanan Dinas Rutin Koordinasi dan Konsultasi dengan Kantor Pusat dan Instansi Terkait | K22: 1 | L22: Thn | M22: 117366000 | N22: =K22*M22 -> 117366000 | O22: 344000 | V22: 42031700
A23: 524113 | B23: Belanja Perjalanan Dinas Dalam Kota | F23: =F25 -> 10560000 | I23: 524113 | J23: Belanja Perjalanan Dinas Dalam Kota | N23: =N25 -> 10560000 | O23: =O25 -> 0 | V23: 2880000
B24: (KPPN. 135-Surabaya II) | J24: (KPPN. 135-Surabaya II)
B25: - Perjalanan Dinas Dalam Kota | C25: 1 | D25: Thn | E25: 10560000 | F25: =C25*E25 -> 10560000 | J25: - Perjalanan Dinas Dalam Kota | K25: 1 | L25: Thn | M25: 10560000 | N25: =K25*M25 -> 10560000 | V25: 2880000
A26: 524114 | B26: Belanja Perjalanan Dinas Paket Meeting Dalam Kota | F26: =F28 -> 2040000 | I26: 524114 | J26: Belanja Perjalanan Dinas Paket Meeting Dalam Kota | N26: =N28 -> 2040000 | O26: =O28 -> 0 | V26: 2040000
B27: (KPPN. 135-Surabaya II) | J27: (KPPN. 135-Surabaya II)
B28: - Perjalanan Dinas Menghadiri Undangan rapat/asistensi/bimtek/diklat | C28: 1 | D28: Thn | E28: 2040000 | F28: =C28*E28 -> 2040000 | J28: - Perjalanan Dinas Menghadiri Undangan rapat/asistensi/bimtek/diklat | K28: 1 | L28: Thn | M28: 2040000 | N28: =K28*M28 -> 2040000 | V28: 2040000
A29: 524119 | B29: Belanja Perjalanan Dinas Paket Meeting Luar Kota | F29: =F31 -> 259567000 | I29: 524119 | J29: Belanja Perjalanan Dinas Paket Meeting Luar Kota | N29: =N31 -> 260671000 | O29: =O31 -> 0 | V29: 26561109
B30: (KPPN. 135-Surabaya II) | J30: (KPPN. 135-Surabaya II)
B31: - Perjalanan Dinas Menghadiri Undangan rapat/asistensi/bimtek/diklat | C31: 1 | D31: Thn | E31: 259567000 | F31: =C31*E31 -> 259567000 | J31: - Perjalanan Dinas Menghadiri Undangan rapat/asistensi/bimtek/diklat | K31: 1 | L31: Thn | M31: 260671000 | N31: =K31*M31 -> 260671000 | Q31: =F31-N31 -> -1104000 | T31: =N31-F31 -> 1104000 | V31: 26561109
A32: C | B32: Penambah Daya Tahan Tubuh | F32: =SUM(F33) -> 326040000 | I32: C | J32: Penambah Daya Tahan Tubuh | N32: =SUM(N33) -> 298584000 | O32: =SUM(#REF!) -> #REF! | V32: 109136000
A33: 521113 | B33: Belanja Penambah Daya Tahan Tubuh | F33: =F35 -> 326040000 | I33: 521113 | J33: Belanja Penambah Daya Tahan Tubuh | N33: =N35 -> 298584000 | V33: 109136000
B34: (KPPN. 135-Surabaya II) | J34: (KPPN. 135-Surabaya II) | K34: =65*22*12 -> 17160 | L34: =65*12 -> 780 | O34: =N35-O35 -> 544000
B35: - Makanan/Minuman Penambah Daya Tahan Tubuh [65 org x 22 hari x 12 bulan] | C35: =65*22*12 -> 17160 | D35: OK | E35: 19000 | F35: =E35*C35 -> 326040000 | J35: - Makanan/Minuman Penambah Daya Tahan Tubuh [65 org x 22 hari x 12 bulan] | K35: 17160 | L35: OK | M35: 17400 | N35: =M35*K35 -> 298584000 | O35: =F35-28000000 -> 298040000 | R35: =F35-N35 -> 27456000 | T35: =N35-F35 -> -27456000 | V35: 109136000
A36: 102 | B36: Peningkatan Sarana Prasarana Perkantoran | F36: =SUM(F37) -> 11000000 | G36: U | I36: 102 | J36: Peningkatan Sarana Prasarana Perkantoran | N36: =SUM(N37) -> 11000000 | V36: 142000
A37: A | B37: Pembuatan Laporan Kinerja (LAKIN) | F37: =SUM(F38) -> 11000000 | I37: A | J37: Pembuatan Laporan Kinerja (LAKIN) | N37: =SUM(N38) -> 11000000 | V37: 142000
A38: 521119 | B38: Belanja Barang Operasional Lainnya | F38: =SUM(F40:F40) -> 11000000 | I38: 521119 | J38: Belanja Barang Operasional Lainnya | N38: =SUM(N40:N40) -> 11000000 | V38: 142000
B39: (KPPN. 135-Surabaya II) | J39: (KPPN. 135-Surabaya II)
B40: - Biaya Editing dan Cetak Buku LAKIN 2025 | C40: 1 | D40: Paket | E40: 11000000 | F40: =E40*C40 -> 11000000 | J40: - Biaya Editing dan Cetak Buku LAKIN 2025 | K40: 1 | L40: Paket | M40: 11000000 | N40: =M40*K40 -> 11000000 | V40: 142000
A41: 103 | B41: Dukungan Tupoksi | F41: =F42+F46+F74+F85+F100+F107+F115+F124+F131+F150+F158+F186+F194+F203 -> 1093295000 | G41: U | I41: 103 | J41: Dukungan Tupoksi | N41: =N42+N46+N74+N85+N100+N107+N115+N124+N131+N150+N158+N186+N194+N203 -> 1186647000 | V41: 602490394
...

Sheet Sisa
B2: 7437.BAH.078 | K2: =SUM(K3:K16) -> 146141000
B3: 1 | C3: Standar Biaya Masukan Lainnya (SBML) | D3: 1 | E3: Thn | F3: 1415000000 | G3: 1415000000 | K3: ='RAB Rev 9'!R17 -> 67000000
B4: 2 | C4: Makanan/Minuman Penambah Daya Tahan Tubuh [65 org x 22 hari x 12 bulan] | D4: 17160 | E4: OK | F4: 17400 | G4: 298584000 | H4: 298040000 | K4: ='RAB Rev 9'!R35 -> 27456000 | M4: 28861000 | N4: =M4-K4 -> 1405000
B5: 3 | C5: BBM Koordinasi Persiapan Sosialisasi MOTS ( 50 ltr x 1 Mbl x 3 Hari x 1 keg) | D5: 0 | E5: Ltr | F5: 12800 | G5: 0 | K5: ='RAB Rev 9'!R60 -> 1920000
B6: 4 | C6: BBM Monev Rutin ISR, MOTS ( 40 ltr x 1 Mbl x 3 Hari x 2 Keg) | D6: 0 | E6: Ltr | F6: 12800 | G6: 0 | K6: ='RAB Rev 9'!R61 -> 3072000
B7: 5 | C7: BBM Operasional pemeriksaan rutin Alkom [ 21 liter x 1 mbl x 5 hari x 3 keg] | D7: 316 | E7: Liter | F7: 13000 | G7: 4108000 | K7: ='RAB Rev 9'!R77 -> 5310000
B8: 6 | C8: BBM Operasional pemeriksaan rutin SMFR [ 45 liter x 1 mbl x 5 hari x 6 keg] | D8: 1350 | E8: Liter | F8: 13000 | G8: 17550000 | K8: ='RAB Rev 9'!R78 -> 1011000
B9: 7 | C9: BBM Operasional inspeksi Validasi Izin Stasiun Radio Dalam Kota [ 30 liter x 1 mbl x 5 hari x 3 keg] | D9: 140 | E9: Liter | F9: 13000 | G9: 1820000 | K9: ='RAB Rev 9'!R103 -> 3888000
B10: 8 | C10: BBM Inspeksi Validasi Izin Stasiun Radio Luar Kota (45 ltr x 1 Mbl x 5 hari x 12 Keg) | D10: 2075 | E10: Liter | F10: 12800 | G10: 26560000 | K10: ='RAB Rev 9'!R110 -> 6144000
B11: 9 | C11: Sewa kendaraan Roda 4 (Inspeksi Validasi Izin Stasiun Radio Luar Kota Transportasi Udara) (1 Mbl x 5 hari x 1 keg) | D11: 1 | E11: Paket | F11: 2060000 | G11: 2060000 | K11: ='RAB Rev 9'!R118 -> 4000000
B12: 10 | C12: BBM Koordinasi Lokal UNAR (40 ltr x 1 mbl x 3 hari x 4 keg) | D12: 335 | E12: Liter | F12: 12800 | G12: 4288000 | K12: ='RAB Rev 9'!R138 -> 1884000
B13: 11 | C13: Sewa Laptop ( 36 buah x 1 hari x 5 keg) UNAR | D13: 180 | E13: OH | F13: 175000 | G13: 31500000 | K13: ='RAB Rev 9'!R157 -> 12500000
B14: 12 | C14: Sewa Kendaraan [1 mbl x 3 hari x 2 keg] Pemeriksaan BMN Luar Kota | D14: 6 | E14: UH | F14: 1212000 | G14: 7272000 | K14: ='RAB Rev 9'!R189 -> 3636000
B15: 13 | C15: BBM luar Kota [ 45 liter x 1 mbl x 5 hari x 5 keg] Pencegahan Piutang BHP Frekuensi Radio | D15: 625 | E15: Liter | F15: 12800 | G15: 8000000 | K15: ='RAB Rev 9'!R206 -> 6400000
B16: 14 | C16: BBM dalam Kota [ 14 liter x 1 mbl x 5 hari x 3 keg] Pencegahan Piutang BHP Frekuensi Radio | D16: 145 | E16: Liter | F16: 12800 | G16: 1856000 | K16: ='RAB Rev 9'!R207 -> 1920000
B18: 7437.BAH.U07 | K18: =K19 -> #VALUE! | L18: =K18+K20+K22 -> #VALUE!
B19: 1 | C19: BBM Operasional (38 liter x 1 Mbl x 5 Hari x 6 Keg) | D19: 540 | E19: liter | F19: 12800 | G19: 6912000 | K19: ='rab rev 9'!#ref! -> #VALUE!
B20: 7437.BAH.U08 | K20: =K21 -> #VALUE!
C21: BBM Operasional (32 liter x 1 Mbl x 5 Hari x 50 Keg) | D21: 8000 | E21: liter | F21: 12800 | G21: 102400000 | K21: ='rab rev 9'!#ref! -> #VALUE!
B22: 7437.BAH.U11 | K22: =SUM(K23:K24) -> #VALUE!
C23: BBM Operasional (27 liter x 1 Mbl x 5 Hari x 5 Keg) | D23: 675 | E23: liter | F23: 12800 | G23: 8640000 | K23: ='rab rev 9'!#ref! -> #VALUE!
C24: BBM Pelaksanaan Penertiban Luar Kota (25ltr x 1 Mbl x 5 hr x 5 keg) | D24: 625 | E24: Liter | F24: 12800 | G24: 8000000 | K24: ='rab rev 9'!#ref! -> #VALUE!
B25: 994.002 | K25: =SUM(K26:K30) -> 158770000 | L25: 158770000
C26: Biaya Tenaga Kontraktual (2 Satpam, 2 Cleaning Service) ( 4 org x 13bln) | D26: 52 | E26: OB | F26: 5240000 | G26: 272480000 | K26: ='RAB Rev 9'!R346 -> 104520000
C27: Honor Pejabat Pembuat Komitmen (PPK) | D27: 1 | E27: Paket | F27: 15750000 | G27: 15750000 | K27: ='RAB Rev 9'!R363 -> 5250000
C28: Sewa mesin fotokopi | D28: 12 | E28: UB | F28: 4100000 | G28: 49200000 | K28: ='RAB Rev 9'!R379 -> 15000000
C29: Listrik | D29: 1 | E29: Thn | F29: 342982000 | G29: 342982000 | K29: ='RAB Rev 9'!R412 -> 20000000
C30: Langganan jaringan internet kantor Balmon Surabaya (100 Mbps) | D30: 1 | E30: Thn | F30: 295400000 | G30: 295400000 | K30: ='RAB Rev 9'!R421 -> 14000000
B31: 994.960 | K31: =K32 -> 3500000 | L31: 3500000
C32: Paket Data Pengukuran Kualitas Layanan Telekomunikasi | K32: 3500000
K33: =K2+K18+K20+K22+K25+K31 -> #VALUE!

Sheet Usulan
B1: Rencana Revisi 9
B2: 7437.BAH.078 | D2: =SUM(D3:D11) -> 141908000 | E2: =SUM(E3:E11) -> 146141000 | F2: =SUM(F3:F11) -> 146141000
A3: 078.103A | B3: 1 | C3: 000019. Biaya Operasional Genset | D3: 19200000 | E3: 20208000 | F3: 20208000
A4: 078.103I | B4: 2 | C4: BBM Pengukuran Kualitas Layanan Telekomunikasi (QOS) Dalam Kota (32 ltr x 1 Mbl x 5 hari x 2 keg) | D4: 1248000 | E4: 1248000 | F4: 1248000
A5: 078.103L | B5: 3 | C5: Sewa Laptop (35 unit x 1 hari x 4 keg) UNAR | D5: 3500000 | E5: 3500000 | F5: 3500000
A6: 078.103N | B6: 4 | C6: Seminar Kit Capkin | D6: =300000*60 -> 18000000 | E6: 18000000 | F6: 17900000 | G6: 521211
A7: 078.103E | B7: 5 | C7: Pengadaan Seminar Kit Pemusnahan | D7: =100*300000 -> 30000000 | E7: 30000000 | F7: 30000000 | G7: 521211
A8: 078.103E | B8: 6 | C8: Pengadaan Perlengkapan Pegawai Teknis | E8: =D9+D10 -> 49055000 | F8: 49055000
C9: - Baju Teknis | D9: =67*665000 -> 44555000 | G9: 521211
C10: - Seragam Upacara | D10: =6*750000 -> 4500000
A11: 078.103N | B11: 7 | C11: Pembuatan Video ILM ZI | D11: 20905000 | E11: 24130000 | F11: 24230000
B13: 994.002 | D13: =SUM(D14:D22) -> 158770000 | E13: =SUM(E14:E22) -> 158770000 | F13: =Sisa!K25-Usulan!E13 -> 0
B14: 1 | C14: Keperluan Sehari hari perkantoran | D14: 12770000 | E14: 12770000
B15: 2 | C15: Perbaikan Interior Mobil Monitor | D15: 15000000 | E15: 15000000 | F15: Kendaraan Operasional
B16: 3 | C16: Perbaikan Rudin | D16: 48000000 | E16: 48000000 | F16: Pemeliharaan Gedung Kantor | G16: =D16-E16 -> 0
B17: 4 | C17: Biaya Langganan Aplikasi Artificial Intelligence | D17: 3000000 | E17: 3000000
C18: - Langganan Claude
C19: - langganan Canva
B20: 5 | C20: Biaya Langganan Aplikasi Remote Desktop | D20: 5000000 | E20: 5000000 | F20: detail baru
B21: 6 | C21: Perbaikan Genset | D21: 30000000 | E21: 30000000
B22: 7 | C22: Pemeliharaan Inventaris | D22: 45000000 | E22: 45000000
G23: =D13-E13 -> 0
B24: 994.960 | D24: =D25 -> 3500000 | E24: 3500000 | F24: =Sisa!L31-Usulan!E24 -> 0
B25: 1 | C25: Langganan Lisensi Aplikasi Video Conference dan aplikasi teknis | D25: =SUM(D26:D30) -> 3500000
C26: - Cloud TU 2TB | D26: 1500000
C27: - Cloud Kuala 200GB | D27: 500000
C28: - Cloud Montib 200GB | D28: 500000
C29: - Cloud Sarpras Mola 200GB | D29: 500000
C30: - Langganan Akun Ig | D30: 500000
C31: Total Revisi | D31: =D24+D13+D2 -> 304178000

Sheet MAK
B3: 7437.BAH
B4: 7437.BAH.078 | C4: ='rab rev 9'!#ref! -> #VALUE! | D4: =C4 -> #VALUE!
B5: 7437.BAH.U07 | C5: ='rab rev 9'!#ref! -> #VALUE!
B6: 7437.BAH.U08 | C6: ='rab rev 9'!#ref! -> #VALUE!
B7: 7437.BAH.U10 | C7: ='rab rev 9'!#ref! -> #VALUE!
B8: 7437.BAH.U11 | C8: ='rab rev 9'!#ref! -> #VALUE!
C9: =SUM(C4:C8) -> #VALUE! | D9: =SUM(D4:D8) -> #VALUE!
F10: =241.667 -> 241.667
B11: 7427.EBA.994 | F11: =F10*16000 -> 3866672
B12: 994.001 | C12: 0
B13: 994.002 | C13: ='rab rev 9'!#ref! -> #VALUE!
C14: =SUM(C12:C13) -> #VALUE!
B15: TOTAL | C15: =C9+C14 -> #VALUE!

Sheet datduk
C2: Pagu | D2: realisasi | E2: Sisa | F2: Est s/d Des | G2: Revisi | H2: Tambah
B3: 000019. Biaya Operasional Genset | C3: 56832000 | D3: 45385400 | E3: =C3-D3 -> 11446600 | F3: =6000000*4 -> 24000000 | G3: 69385000 | H3: =G3-C3 -> 12553000
H4: =C3+H3 -> 69385000
